<?xml version="1.0"?>
<!-- This URDF was automatically created by SolidWorks to URDF Exporter! Originally created by Stephen Brawner (brawner@gmail.com) 
     Commit Version: 1.6.0-4-g7f85cfe  Build Version: 1.6.7995.38578
     For more information, please see http://wiki.ros.org/sw_urdf_exporter -->
<robot
  name="welding_robot">
  <link name="world"/>
    <joint name="base_joint" type="fixed">
    <parent link="world"/>
    <child link="base_link"/>
    <origin rpy="0 0 0" xyz="0.0 0.0 0.0"/>
  </joint>
  <link
    name="base_link">
    <inertial>
      <origin
        xyz="-0.055092 0.00050348 0.081633"
        rpy="0 0 0" />
      <mass
        value="24.355" />
      <inertia
        ixx="0.26628"
        ixy="0.0031172"
        ixz="0.019003"
        iyy="0.51507"
        iyz="-0.001216"
        izz="0.67125" />
    </inertial>
    <visual>
      <origin
        xyz="0 0 0"
        rpy="0 0 0" />
      <geometry>
        <mesh
          filename="package://Model_Robot/meshes/base_link.STL" />
      </geometry>
      <material
        name="">
        <color
          rgba="0.79608 0.82353 0.93725 1" />
      </material>
    </visual>
    <collision>
      <origin
        xyz="0 0 0"
        rpy="0 0 0" />
      <geometry>
        <mesh
          filename="package://Model_Robot/meshes/base_link.STL" />
      </geometry>
    </collision>
  </link>
  <link
    name="link_1">
    <inertial>
      <origin
        xyz="0.043093 -0.029565 0.15211"
        rpy="0 0 0" />
      <mass
        value="37.864" />
      <inertia
        ixx="0.88479"
        ixy="0.00066848"
        ixz="-0.27163"
        iyy="1.0858"
        iyz="0.022691"
        izz="0.95843" />
    </inertial>
    <visual>
      <origin
        xyz="0 0 0"
        rpy="0 0 0" />
      <geometry>
        <mesh
          filename="package://Model_Robot/meshes/link_1.STL" />
      </geometry>
      <material
        name="">
        <color
          rgba="0.79608 0.82353 0.93725 1" />
      </material>
    </visual>
    <collision>
      <origin
        xyz="0 0 0"
        rpy="0 0 0" />
      <geometry>
        <mesh
          filename="package://Model_Robot/meshes/link_1.STL" />
      </geometry>
    </collision>
  </link>
  <joint
    name="joint_1"
    type="revolute">
    <origin
      xyz="0 0 0.159"
      rpy="0 0 0" />
    <parent
      link="base_link" />
    <child
      link="link_1" />
    <axis
      xyz="0 0 1" />
    <limit
      lower="-1.92"
      upper="2.18"
      effort="50"
      velocity="3.14" />
  </joint>
  <link
    name="link_2">
    <inertial>
      <origin
        xyz="0.32253 0.016769 0.065572"
        rpy="0 0 0" />
      <mass
        value="13.122" />
      <inertia
        ixx="0.061393"
        ixy="-0.0098487"
        ixz="-0.0056629"
        iyy="0.72146"
        iyz="-0.0032035"
        izz="0.75021" />
    </inertial>
    <visual>
      <origin
        xyz="0 0 0"
        rpy="0 0 0" />
      <geometry>
        <mesh
          filename="package://Model_Robot/meshes/link_2.STL" />
      </geometry>
      <material
        name="">
        <color
          rgba="0.79608 0.82353 0.93725 1" />
      </material>
    </visual>
    <collision>
      <origin
        xyz="0 0 0"
        rpy="0 0 0" />
      <geometry>
        <mesh
          filename="package://Model_Robot/meshes/link_2.STL" />
      </geometry>
    </collision>
  </link>
  <joint
    name="joint_2"
    type="revolute">
    <origin
      xyz="0.185 -0.088997 0.368"
      rpy="1.5708 -1.4486 0" />
    <parent
      link="link_1" />
    <child
      link="link_2" />
    <axis
      xyz="0 0 1" />
    <limit
      lower="-2.0"
      upper="1.83"
      effort="50"
      velocity="3.05" />
  </joint>
  <link
    name="link_3">
    <inertial>
      <origin
        xyz="0.11621 -0.12279 -0.043519"
        rpy="0 0 0" />
      <mass
        value="12.871" />
      <inertia
        ixx="0.17797"
        ixy="0.071595"
        ixz="-0.011927"
        iyy="0.17913"
        iyz="0.0062443"
        izz="0.23317" />
    </inertial>
    <visual>
      <origin
        xyz="0 0 0"
        rpy="0 0 0" />
      <geometry>
        <mesh
          filename="package://Model_Robot/meshes/link_3.STL" />
      </geometry>
      <material
        name="">
        <color
          rgba="0.79608 0.82353 0.93725 1" />
      </material>
    </visual>
    <collision>
      <origin
        xyz="0 0 0"
        rpy="0 0 0" />
      <geometry>
        <mesh
          filename="package://Model_Robot/meshes/link_3.STL" />
      </geometry>
    </collision>
  </link>
  <joint
    name="joint_3"
    type="revolute">
    <origin
      xyz="0.76 0 0"
      rpy="0 0 0.12217" />
    <parent
      link="link_2" />
    <child
      link="link_3" />
    <axis
      xyz="0 0 1" />
    <limit
      lower="-1.5"
      upper="3.9"
      effort="50"
      velocity="3.26" />
  </joint>
  <link
    name="link_4">
    <inertial>
      <origin
        xyz="-0.00015162 1.2749E-05 0.32065"
        rpy="0 0 0" />
      <mass
        value="10.964" />
      <inertia
        ixx="0.59366"
        ixy="-4.9178E-06"
        ixz="-0.00045563"
        iyy="0.59059"
        iyz="0.00014174"
        izz="0.030107" />
    </inertial>
    <visual>
      <origin
        xyz="0 0 0"
        rpy="0 0 0" />
      <geometry>
        <mesh
          filename="package://Model_Robot/meshes/link_4.STL" />
      </geometry>
      <material
        name="">
        <color
          rgba="0.79608 0.82353 0.93725 1" />
      </material>
    </visual>
    <collision>
      <origin
        xyz="0 0 0"
        rpy="0 0 0" />
      <geometry>
        <mesh
          filename="package://Model_Robot/meshes/link_4.STL" />
      </geometry>
    </collision>
  </link>
  <joint
    name="joint_4"
    type="revolute">
    <origin
      xyz="0.15 -0.25 -0.088997"
      rpy="-1.5708 0 3.1416" />
    <parent
      link="link_3" />
    <child
      link="link_4" />
    <axis
      xyz="0 0 1" />
    <limit
      lower="-3.49"
      upper="3.49"
      effort="39.2"
      velocity="6.98" />
  </joint>
  <link
    name="link_5">
    <inertial>
      <origin
        xyz="0 0.00070374 -0.016382"
        rpy="0 0 0" />
      <mass
        value="0.64718" />
      <inertia
        ixx="0.0010097"
        ixy="5.5021E-21"
        ixz="-1.2847E-20"
        iyy="0.001063"
        iyz="5.7299E-06"
        izz="0.00061302" />
    </inertial>
    <visual>
      <origin
        xyz="0 0 0"
        rpy="0 0 0" />
      <geometry>
        <mesh
          filename="package://Model_Robot/meshes/link_5.STL" />
      </geometry>
      <material
        name="">
        <color
          rgba="0.79608 0.82353 0.93725 1" />
      </material>
    </visual>
    <collision>
      <origin
        xyz="0 0 0"
        rpy="0 0 0" />
      <geometry>
        <mesh
          filename="package://Model_Robot/meshes/link_5.STL" />
      </geometry>
    </collision>
  </link>
  <joint
    name="joint_5"
    type="revolute">
    <origin
      xyz="0 0 0.799"
      rpy="0 -1.5708 0" />
    <parent
      link="link_4" />
    <child
      link="link_5" />
    <axis
      xyz="0 1 0" />
    <limit
      lower="-0.9"
      upper="2.44"
      effort="39.2"
      velocity="6.98" />
  </joint>
  <link
    name="link_6">
    <inertial>
      <origin
        xyz="1.0842E-18 7.3024E-05 0.0071715"
        rpy="0 0 0" />
      <mass
        value="0.081492" />
      <inertia
        ixx="3.6198E-05"
        ixy="4.8596E-22"
        ixz="4.8859E-21"
        iyy="3.6454E-05"
        iyz="9.9471E-09"
        izz="6.9103E-05" />
    </inertial>
    <visual>
      <origin
        xyz="0 0 0"
        rpy="0 0 0" />
      <geometry>
        <mesh
          filename="package://Model_Robot/meshes/link_6.STL" />
      </geometry>
      <material
        name="">
        <color
          rgba="0.79608 0.82353 0.93725 1" />
      </material>
    </visual>
    <collision>
      <origin
        xyz="0 0 0"
        rpy="0 0 0" />
      <geometry>
        <mesh
          filename="package://Model_Robot/meshes/link_6.STL" />
      </geometry>
    </collision>
  </link>
  <joint
    name="joint_6"
    type="revolute">
    <origin
      xyz="0 0.0012226 -0.074956"
      rpy="3.1416 0 -1.5708" />
    <parent
      link="link_5" />
    <child
      link="link_6" />
    <axis
      xyz="0 0 1" />
    <limit
      lower="-6.28"
      upper="6.28"
      effort="19.6"
      velocity="10.47" />
  </joint>


  <transmission name="link_1_trans">
    <type>transmission_interface/SimpleTransmission</type>
    <joint name="joint_1">
      <hardwareInterface>hardware_interface/PositionJointInterface</hardwareInterface>
    </joint>
    <actuator name="link_1_motor">
      <hardwareInterface>hardware_interface/PositionJointInterface</hardwareInterface>
      <mechanicalReduction>1</mechanicalReduction>
    </actuator>
  </transmission>

  <transmission name="link_2_trans">
    <type>transmission_interface/SimpleTransmission</type>
    <joint name="joint_2">
      <hardwareInterface>hardware_interface/PositionJointInterface</hardwareInterface>
    </joint>
    <actuator name="link_2_motor">
      <hardwareInterface>hardware_interface/PositionJointInterface</hardwareInterface>
      <mechanicalReduction>1</mechanicalReduction>
    </actuator>
  </transmission>

  <transmission name="link_3_trans">
    <type>transmission_interface/SimpleTransmission</type>
    <joint name="joint_3">
      <hardwareInterface>hardware_interface/PositionJointInterface</hardwareInterface>
    </joint>
    <actuator name="link_3_motor">
      <hardwareInterface>hardware_interface/PositionJointInterface</hardwareInterface>
      <mechanicalReduction>1</mechanicalReduction>
    </actuator>
  </transmission>

  <transmission name="link_4_trans">
    <type>transmission_interface/SimpleTransmission</type>
    <joint name="joint_4">
      <hardwareInterface>hardware_interface/PositionJointInterface</hardwareInterface>
    </joint>
    <actuator name="link_4_motor">
      <hardwareInterface>hardware_interface/PositionJointInterface</hardwareInterface>
      <mechanicalReduction>1</mechanicalReduction>
    </actuator>
  </transmission>

  <transmission name="link_5_trans">
    <type>transmission_interface/SimpleTransmission</type>
    <joint name="joint_5">
      <hardwareInterface>hardware_interface/PositionJointInterface</hardwareInterface>
    </joint>
    <actuator name="link_5_motor">
      <hardwareInterface>hardware_interface/PositionJointInterface</hardwareInterface>
      <mechanicalReduction>1</mechanicalReduction>
    </actuator>
  </transmission>

  <transmission name="link_6_trans">
    <type>transmission_interface/SimpleTransmission</type>
    <joint name="joint_6">
      <hardwareInterface>hardware_interface/PositionJointInterface</hardwareInterface>
    </joint>
    <actuator name="link_6_motor">
      <hardwareInterface>hardware_interface/PositionJointInterface</hardwareInterface>
      <mechanicalReduction>1</mechanicalReduction>
    </actuator>
  </transmission>

  <gazebo reference="link_1">
	  <selfCollide>true</selfCollide>
  </gazebo>

  <gazebo reference="link_2">
	  <selfCollide>true</selfCollide>
  </gazebo>

  <gazebo reference="link_3">
	  <selfCollide>true</selfCollide>
  </gazebo>

  <gazebo reference="link_4">
	  <selfCollide>true</selfCollide>
  </gazebo>

  <gazebo reference="link_5">
	  <selfCollide>true</selfCollide>
  </gazebo>

  <gazebo reference="link_6">
	  <selfCollide>true</selfCollide>
  </gazebo>

  <gazebo>
	  <plugin name="gazebo_ros_control" filename="libgazebo_ros_control.so">
		  <robotNamespace>/welding_robot</robotNamespace>
	  </plugin>
  </gazebo>


</robot>
